Workbook

Sheet Hoja1
A2: Clase | B2: Gastos
A3: Clase2 | B3: (Todas)
A4: Tipo | B4: Resultado
A5: Grupo | B5: (Todas)
A6: Categoría | B6: (Todas)
A9: Nombre Grupo | B9: Cuenta | C9: Nombre Cuenta
A10: Administrativos | B10: 5105 | C10: Gastos de personal
B11: 5110 | C11: Honorarios
B12: 5115 | C12: Impuestos
B13: 5120 | C13: Arrendamientos
B14: 5130 | C14: Seguros
B15: 5135 | C15: Servicios
B16: 5140 | C16: Gastos legales
B17: 5145 | C17: Mantenimiento y reparaciones
B18: 5150 | C18: Adecuación e instalación
B19: 5155 | C19: Gastos de viaje
B20: 5160 | C20: Depreciaciones
B21: 5165 | C21: Amortizaciones
B22: 5195 | C22: Diversos
... B24: 5199 | C24: Otros gastos
A25: Impuesto De Renta Y Complementarios | B25: 5405 | C25: Impuesto de renta y complementarios
A26: Otros Gastos De Actividades Ordinarias | B26: 5305 | C26: Financieros
B27: 5315 | C27: Gastos extraordinarios
B28: 5395 | C28: Gastos diversos
A29: Ventas | B29: 5205 | C29: Gastos de personal
B30: 5235 | C30: Servicios
B31: 5295 | C31: Diversos
A32: Total general

Sheet Accounts
A1: Orden | B1: Código | C1: Nombre | D1: Categoría | E1: Clase | F1: Relación con | G1: Maneja vencimientos | H1: Diferencia fiscal | I1: Activo | J1: Nivel agrupación | K1: Clase | L1: Nombre Clase | M1: Tipo | N1: Grupo | O1: Nombre Grupo | P1: Cuenta | Q1: Nombre Cuenta | R1: EBITDA | S1: Termino
A2: 5 | B2: 11050501 | C2: Caja general | D2: Caja - Bancos | E2: Activo | F2: Sin asignar | G2: No maneja vencimiento | H2: No | I2: Sí | J2: Transaccional | K2: =VALUE(LEFT(B2)) -> 1 | L2: =VLOOKUP(K2,List!$B$1:$D$10,2,0) -> Activo | M2: =VLOOKUP(K2,List!$B$1:$D$10,3,0) -> Balance | N2: =LEFT(B2,2) -> 11 | O2: =VLOOKUP(N2,List!$F$1:$G$36,2,0) -> Efectivo Y Equivalentes De Efectivo | P2: =LEFT(B2,4) -> 1105 | Q2: =VLOOKUP(P2,PUC!$A$7:$B$869,2,0) -> Caja | R2: NO | S2: =VLOOKUP(N2,List!$F:$H,3,0) -> Corto Termino
A3: 7 | B3: 11051001 | C3: Cajas menores | D3: Caja - Bancos | E3: Activo | F3: Sin asignar | G3: No maneja vencimiento | H3: No | I3: Sí | J3: Transaccional | K3: =VALUE(LEFT(B3)) -> 1 | L3: =VLOOKUP(K3,List!$B$1:$D$10,2,0) -> Activo | M3: =VLOOKUP(K3,List!$B$1:$D$10,3,0) -> Balance | N3: =LEFT(B3,2) -> 11 | O3: =VLOOKUP(N3,List!$F$1:$G$36,2,0) -> Efectivo Y Equivalentes De Efectivo | P3: =LEFT(B3,4) -> 1105 | Q3: =VLOOKUP(P3,PUC!$A$7:$B$869,2,0) -> Caja | R3: NO | S3: =VLOOKUP(N3,List!$F:$H,3,0) -> Corto Termino
A4: 8 | B4: 11051002 | C4: Caja Menor Admon | D4: Caja - Bancos | E4: Activo | F4: Sin asignar | G4: No maneja vencimiento | H4: No | I4: Sí | J4: Transaccional | K4: =VALUE(LEFT(B4)) -> 1 | L4: =VLOOKUP(K4,List!$B$1:$D$10,2,0) -> Activo | M4: =VLOOKUP(K4,List!$B$1:$D$10,3,0) -> Balance | N4: =LEFT(B4,2) -> 11 | O4: =VLOOKUP(N4,List!$F$1:$G$36,2,0) -> Efectivo Y Equivalentes De Efectivo | P4: =LEFT(B4,4) -> 1105 | Q4: =VLOOKUP(P4,PUC!$A$7:$B$869,2,0) -> Caja | R4: NO | S4: =VLOOKUP(N4,List!$F:$H,3,0) -> Corto Termino
A5: 11 | B5: 11100501 | C5: Moneda nacional | D5: Caja - Bancos | E5: Activo | F5: Sin asignar | G5: No maneja vencimiento | H5: No | I5: Sí | J5: Transaccional | K5: =VALUE(LEFT(B5)) -> 1 | L5: =VLOOKUP(K5,List!$B$1:$D$10,2,0) -> Activo | M5: =VLOOKUP(K5,List!$B$1:$D$10,3,0) -> Balance | N5: =LEFT(B5,2) -> 11 | O5: =VLOOKUP(N5,List!$F$1:$G$36,2,0) -> Efectivo Y Equivalentes De Efectivo | P5: =LEFT(B5,4) -> 1110 | Q5: =VLOOKUP(P5,PUC!$A$7:$B$869,2,0) -> Bancos | R5: NO | S5: =VLOOKUP(N5,List!$F:$H,3,0) -> Corto Termino
A6: 12 | B6: 11100502 | C6: Pagos en línea | D6: Caja - Bancos | E6: Activo | F6: Formas de pago | G6: No maneja vencimiento | H6: No | I6: Sí | J6: Transaccional | K6: =VALUE(LEFT(B6)) -> 1 | L6: =VLOOKUP(K6,List!$B$1:$D$10,2,0) -> Activo | M6: =VLOOKUP(K6,List!$B$1:$D$10,3,0) -> Balance | N6: =LEFT(B6,2) -> 11 | O6: =VLOOKUP(N6,List!$F$1:$G$36,2,0) -> Efectivo Y Equivalentes De Efectivo | P6: =LEFT(B6,4) -> 1110 | Q6: =VLOOKUP(P6,PUC!$A$7:$B$869,2,0) -> Bancos | R6: NO | S6: =VLOOKUP(N6,List!$F:$H,3,0) -> Corto Termino
A7: 13 | B7: 11100503 | C7: Pagos en línea Mercado Pago | D7: Caja - Bancos | E7: Activo | F7: Formas de pago | G7: No maneja vencimiento | H7: No | I7: Sí | J7: Transaccional | K7: =VALUE(LEFT(B7)) -> 1 | L7: =VLOOKUP(K7,List!$B$1:$D$10,2,0) -> Activo | M7: =VLOOKUP(K7,List!$B$1:$D$10,3,0) -> Balance | N7: =LEFT(B7,2) -> 11 | O7: =VLOOKUP(N7,List!$F$1:$G$36,2,0) -> Efectivo Y Equivalentes De Efectivo | P7: =LEFT(B7,4) -> 1110 | Q7: =VLOOKUP(P7,PUC!$A$7:$B$869,2,0) -> Bancos | R7: NO | S7: =VLOOKUP(N7,List!$F:$H,3,0) -> Corto Termino
A8: 16 | B8: 11200501 | C8: BANCOLOMBIA CUENTA AHORROS 206-000311-48 | D8: Caja - Bancos | E8: Activo | F8: Sin asignar | G8: No maneja vencimiento | H8: No | I8: Sí | J8: Transaccional | K8: =VALUE(LEFT(B8)) -> 1 | L8: =VLOOKUP(K8,List!$B$1:$D$10,2,0) -> Activo | M8: =VLOOKUP(K8,List!$B$1:$D$10,3,0) -> Balance | N8: =LEFT(B8,2) -> 11 | O8: =VLOOKUP(N8,List!$F$1:$G$36,2,0) -> Efectivo Y Equivalentes De Efectivo | P8: =LEFT(B8,4) -> 1120 | Q8: =VLOOKUP(P8,PUC!$A$7:$B$869,2,0) -> Cuentas de ahorro | R8: NO | S8: =VLOOKUP(N8,List!$F:$H,3,0) -> Corto Termino
A9: 17 | B9: 11200502 | C9: CAJA SOCIAL CUENTA AHORROS 24097494078 | D9: Caja - Bancos | E9: Activo | F9: Sin asignar | G9: No maneja vencimiento | H9: No | I9: Sí | J9: Transaccional | K9: =VALUE(LEFT(B9)) -> 1 | L9: =VLOOKUP(K9,List!$B$1:$D$10,2,0) -> Activo | M9: =VLOOKUP(K9,List!$B$1:$D$10,3,0) -> Balance | N9: =LEFT(B9,2) -> 11 | O9: =VLOOKUP(N9,List!$F$1:$G$36,2,0) -> Efectivo Y Equivalentes De Efectivo | P9: =LEFT(B9,4) -> 1120 | Q9: =VLOOKUP(P9,PUC!$A$7:$B$869,2,0) -> Cuentas de ahorro | R9: NO | S9: =VLOOKUP(N9,List!$F:$H,3,0) -> Corto Termino
A10: 20 | B10: 11450501 | C10: Fiducias | D10: Caja - Bancos | E10: Activo | F10: Sin asignar | G10: No maneja vencimiento | H10: No | I10: Sí | J10: Transaccional | K10: =VALUE(LEFT(B10)) -> 1 | L10: =VLOOKUP(K10,List!$B$1:$D$10,2,0) -> Activo | M10: =VLOOKUP(K10,List!$B$1:$D$10,3,0) -> Balance | N10: =LEFT(B10,2) -> 11 | O10: =VLOOKUP(N10,List!$F$1:$G$36,2,0) -> Efectivo Y Equivalentes De Efectivo | P10: =LEFT(B10,4) -> 1145 | Q10: =VLOOKUP(P10,PUC!$A$7:$B$869,2,0) -> Inversiones en efectivo | R10: NO | S10: =VLOOKUP(N10,List!$F:$H,3,0) -> Corto Termino
A11: 21 | B11: 11450597 | C11: D. fiscal fiducias | D11: Caja - Bancos | E11: Activo | F11: Sin asignar | G11: No maneja vencimiento | H11: Sí | I11: Sí | J11: Transaccional | K11: =VALUE(LEFT(B11)) -> 1 | L11: =VLOOKUP(K11,List!$B$1:$D$10,2,0) -> Activo | M11: =VLOOKUP(K11,List!$B$1:$D$10,3,0) -> Balance | N11: =LEFT(B11,2) -> 11 | O11: =VLOOKUP(N11,List!$F$1:$G$36,2,0) -> Efectivo Y Equivalentes De Efectivo | P11: =LEFT(B11,4) -> 1145 | Q11: =VLOOKUP(P11,PUC!$A$7:$B$869,2,0) -> Inversiones en efectivo | R11: NO | S11: =VLOOKUP(N11,List!$F:$H,3,0) -> Corto Termino
A12: 25 | B12: 12053501 | C12: Comercio al por mayor y al por menor | D12: Otros activos | E12: Activo | F12: Sin asignar | G12: No maneja vencimiento | H12: No | I12: Sí | J12: Transaccional | K12: =VALUE(LEFT(B12)) -> 1 | L12: =VLOOKUP(K12,List!$B$1:$D$10,2,0) -> Activo | M12: =VLOOKUP(K12,List!$B$1:$D$10,3,0) -> Balance | N12: =LEFT(B12,2) -> 12 | O12: =VLOOKUP(N12,List!$F$1:$G$36,2,0) -> Inversiones En Asociadas | P12: =LEFT(B12,4) -> 1205 | Q12: =VLOOKUP(P12,PUC!$A$7:$B$869,2,0) -> Acciones | R12: NO | S12: =VLOOKUP(N12,List!$F:$H,3,0) -> Corto Termino
A13: 26 | B13: 12053502 | C13: Reajuste fiscal | D13: Otros activos | E13: Activo | F13: Sin asignar | G13: No maneja vencimiento | H13: No | I13: Sí | J13: Transaccional | K13: =VALUE(LEFT(B13)) -> 1 | L13: =VLOOKUP(K13,List!$B$1:$D$10,2,0) -> Activo | M13: =VLOOKUP(K13,List!$B$1:$D$10,3,0) -> Balance | N13: =LEFT(B13,2) -> 12 | O13: =VLOOKUP(N13,List!$F$1:$G$36,2,0) -> Inversiones En Asociadas | P13: =LEFT(B13,4) -> 1205 | Q13: =VLOOKUP(P13,PUC!$A$7:$B$869,2,0) -> Acciones | R13: NO | S13: =VLOOKUP(N13,List!$F:$H,3,0) -> Corto Termino
... A103: 173 | B103: 17202001 | C103: Negocios conjuntos | D103: Otros activos | E103: Activo | F103: Sin asignar | G103: No maneja vencimiento | H103: No | I103: Sí | J103: Transaccional | K103: =VALUE(LEFT(B103)) -> 1 | L103: =VLOOKUP(K103,List!$B$1:$D$10,2,0) -> Activo | M103: =VLOOKUP(K103,List!$B$1:$D$10,3,0) -> Balance | N103: =LEFT(B103,2) -> 17 | O103: =VLOOKUP(N103,List!$F$1:$G$36,2,0) -> Otros Activos No Financieros | P103: =LEFT(B103,4) -> 1720 | Q103: =VLOOKUP(P103,PUC!$A$7:$B$869,2,0) -> Entidades controladas en forma conjunta | R103: NO | S103: =VLOOKUP(N103,List!$F:$H,3,0) -> Largo Termino
A104: 177 | B104: 18050501 | C104: Autorretencion servicios | D104: Otros activos | E104: Activo | F104: Sin asignar | G104: No maneja vencimiento | H104: No | I104: Sí | J104: Transaccional | K104: =VALUE(LEFT(B104)) -> 1 | L104: =VLOOKUP(K104,List!$B$1:$D$10,2,0) -> Activo | M104: =VLOOKUP(K104,List!$B$1:$D$10,3,0) -> Balance | N104: =LEFT(B104,2) -> 18 | O104: Impuesto corriente | P104: =LEFT(B104,4) -> 1805 | Q104: =VLOOKUP(P104,PUC!$A$7:$B$869,2,0) -> Impuesto corriente | R104: NO | S104: =VLOOKUP(N104,List!$F:$H,3,0) -> Corto Termino
A105: 178 | B105: 18050502 | C105: Retención en la fuente compras 1.5% | D105: Otros activos | E105: Activo | F105: Sin asignar | G105: No maneja vencimiento | H105: No | I105: Sí | J105: Transaccional | K105: =VALUE(LEFT(B105)) -> 1 | L105: =VLOOKUP(K105,List!$B$1:$D$10,2,0) -> Activo | M105: =VLOOKUP(K105,List!$B$1:$D$10,3,0) -> Balance | N105: =LEFT(B105,2) -> 18 | O105: Impuesto corriente | P105: =LEFT(B105,4) -> 1805 | Q105: =VLOOKUP(P105,PUC!$A$7:$B$869,2,0) -> Impuesto corriente | R105: NO | S105: =VLOOKUP(N105,List!$F:$H,3,0) -> Corto Termino
A106: 179 | B106: 18050503 | C106: Tarjetas de crédito | D106: Otros activos | E106: Activo | F106: Sin asignar | G106: No maneja vencimiento | H106: No | I106: Sí | J106: Transaccional | K106: =VALUE(LEFT(B106)) -> 1 | L106: =VLOOKUP(K106,List!$B$1:$D$10,2,0) -> Activo | M106: =VLOOKUP(K106,List!$B$1:$D$10,3,0) -> Balance | N106: =LEFT(B106,2) -> 18 | O106: Impuesto corriente | P106: =LEFT(B106,4) -> 1805 | Q106: =VLOOKUP(P106,PUC!$A$7:$B$869,2,0) -> Impuesto corriente | R106: NO | S106: =VLOOKUP(N106,List!$F:$H,3,0) -> Corto Termino
A107: 180 | B107: 18050504 | C107: Servicios 6% | D107: Otros activos | E107: Activo | F107: Sin asignar | G107: No maneja vencimiento | H107: No | I107: Sí | J107: Transaccional | K107: =VALUE(LEFT(B107)) -> 1 | L107: =VLOOKUP(K107,List!$B$1:$D$10,2,0) -> Activo | M107: =VLOOKUP(K107,List!$B$1:$D$10,3,0) -> Balance | N107: =LEFT(B107,2) -> 18 | O107: Impuesto corriente | P107: =LEFT(B107,4) -> 1805 | Q107: =VLOOKUP(P107,PUC!$A$7:$B$869,2,0) -> Impuesto corriente | R107: NO | S107: =VLOOKUP(N107,List!$F:$H,3,0) -> Corto Termino
A108: 181 | B108: 18050505 | C108: Autorretencion | D108: Otros activos | E108: Activo | F108: Sin asignar | G108: No maneja vencimiento | H108: No | I108: Sí | J108: Transaccional | K108: =VALUE(LEFT(B108)) -> 1 | L108: =VLOOKUP(K108,List!$B$1:$D$10,2,0) -> Activo | M108: =VLOOKUP(K108,List!$B$1:$D$10,3,0) -> Balance | N108: =LEFT(B108,2) -> 18 | O108: Impuesto corriente | P108: =LEFT(B108,4) -> 1805 | Q108: =VLOOKUP(P108,PUC!$A$7:$B$869,2,0) -> Impuesto corriente | R108: NO | S108: =VLOOKUP(N108,List!$F:$H,3,0) -> Corto Termino
A109: 182 | B109: 18050506 | C109: Anticipo sobretasa cree | D109: Otros activos | E109: Activo | F109: Sin asignar | G109: No maneja vencimiento | H109: No | I109: Sí | J109: Transaccional | K109: =VALUE(LEFT(B109)) -> 1 | L109: =VLOOKUP(K109,List!$B$1:$D$10,2,0) -> Activo | M109: =VLOOKUP(K109,List!$B$1:$D$10,3,0) -> Balance | N109: =LEFT(B109,2) -> 18 | O109: Impuesto corriente | P109: =LEFT(B109,4) -> 1805 | Q109: =VLOOKUP(P109,PUC!$A$7:$B$869,2,0) -> Impuesto corriente | R109: NO | S109: =VLOOKUP(N109,List!$F:$H,3,0) -> Corto Termino
A110: 183 | B110: 18050507 | C110: Sobrantes en liquidación privada de impuestos | D110: Otros activos | E110: Activo | F110: Sin asignar | G110: No maneja vencimiento | H110: No | I110: Sí | J110: Transaccional | K110: =VALUE(LEFT(B110)) -> 1 | L110: =VLOOKUP(K110,List!$B$1:$D$10,2,0) -> Activo | M110: =VLOOKUP(K110,List!$B$1:$D$10,3,0) -> Balance | N110: =LEFT(B110,2) -> 18 | O110: Impuesto corriente | P110: =LEFT(B110,4) -> 1805 | Q110: =VLOOKUP(P110,PUC!$A$7:$B$869,2,0) -> Impuesto corriente | R110: NO | S110: =VLOOKUP(N110,List!$F:$H,3,0) -> Corto Termino
A111: 187 | B111: 19451001 | C111: De inversiones | D111: Otros activos | E111: Activo | F111: Sin asignar | G111: No maneja vencimiento | H111: No | I111: Sí | J111: Transaccional | K111: =VALUE(LEFT(B111)) -> 1 | L111: =VLOOKUP(K111,List!$B$1:$D$10,2,0) -> Activo | M111: =VLOOKUP(K111,List!$B$1:$D$10,3,0) -> Balance | N111: =LEFT(B111,2) -> 19 | O111: =VLOOKUP(N111,List!$F$1:$G$36,2,0) -> Otros Activos Financieros | P111: =LEFT(B111,4) -> 1945 | Q111: =VLOOKUP(P111,PUC!$A$7:$B$869,2,0) -> De inversiones | R111: NO | S111: =VLOOKUP(N111,List!$F:$H,3,0) -> Corto Termino
A112: 803 | B112: 71050501 | C112: Materia prima | D112: Costo de ventas | E112: Costos de producción o de operación | F112: Sin asignar | G112: No maneja vencimiento | H112: No | I112: Sí | J112: Transaccional | K112: =VALUE(LEFT(B112)) -> 7 | L112: =VLOOKUP(K112,List!$B$1:$D$10,2,0) -> Costos de Servicios | M112: =VLOOKUP(K112,List!$B$1:$D$10,3,0) -> Resultado | N112: =LEFT(B112,2) -> 71 | O112: =VLOOKUP(N112,List!$F$1:$G$36,2,0) -> Costos De Producción O De Operación | P112: =LEFT(B112,4) -> 7105 | Q112: =VLOOKUP(P112,PUC!$A$7:$B$869,2,0) -> Costos de producción o de operación | R112: SI | S112: =VLOOKUP(N112,List!$F:$H,3,0) -> 0
A113: 807 | B113: 72050301 | C113: Salario integral | D113: Gasto - Nómina | E113: Costos de producción o de operación | F113: Sin asignar | G113: No maneja vencimiento | H113: No | I113: Sí | J113: Transaccional | K113: =VALUE(LEFT(B113)) -> 7 | L113: =VLOOKUP(K113,List!$B$1:$D$10,2,0) -> Costos de Servicios | M113: =VLOOKUP(K113,List!$B$1:$D$10,3,0) -> Resultado | N113: =LEFT(B113,2) -> 72 | O113: =VLOOKUP(N113,List!$F$1:$G$36,2,0) -> Mano De Obra Directa | P113: =LEFT(B113,4) -> 7205 | Q113: =VLOOKUP(P113,PUC!$A$7:$B$869,2,0) -> Mano de obra directa | R113: SI | S113: =VLOOKUP(N113,List!$F:$H,3,0) -> 0
A114: 809 | B114: 72050601 | C114: Sueldos | D114: Gasto - Nómina | E114: Costos de producción o de operación | F114: Sin asignar | G114: No maneja vencimiento | H114: No | I114: Sí | J114: Transaccional | K114: =VALUE(LEFT(B114)) -> 7 | L114: =VLOOKUP(K114,List!$B$1:$D$10,2,0) -> Costos de Servicios | M114: =VLOOKUP(K114,List!$B$1:$D$10,3,0) -> Resultado | N114: =LEFT(B114,2) -> 72 | O114: =VLOOKUP(N114,List!$F$1:$G$36,2,0) -> Mano De Obra Directa | P114: =LEFT(B114,4) -> 7205 | Q114: =VLOOKUP(P114,PUC!$A$7:$B$869,2,0) -> Mano de obra directa | R114: SI | S114: =VLOOKUP(N114,List!$F:$H,3,0) -> 0
A115: 811 | B115: 72051201 | C115: Apoyo sostenimiento aprendices | D115: Gasto - Nómina | E115: Costos de producción o de operación | F115: Sin asignar | G115: No maneja vencimiento | H115: No | I115: Sí | J115: Transaccional | K115: =VALUE(LEFT(B115)) -> 7 | L115: =VLOOKUP(K115,List!$B$1:$D$10,2,0) -> Costos de Servicios | M115: =VLOOKUP(K115,List!$B$1:$D$10,3,0) -> Resultado | N115: =LEFT(B115,2) -> 72 | O115: =VLOOKUP(N115,List!$F$1:$G$36,2,0) -> Mano De Obra Directa | P115: =LEFT(B115,4) -> 7205 | Q115: =VLOOKUP(P115,PUC!$A$7:$B$869,2,0) -> Mano de obra directa | R115: SI | S115: =VLOOKUP(N115,List!$F:$H,3,0) -> 0
A116: 813 | B116: 72051501 | C116: Horas extras y recargos | D116: Gasto - Nómina | E116: Costos de producción o de operación | F116: Sin asignar | G116: No maneja vencimiento | H116: No | I116: Sí | J116: Transaccional | K116: =VALUE(LEFT(B116)) -> 7 | L116: =VLOOKUP(K116,List!$B$1:$D$10,2,0) -> Costos de Servicios | M116: =VLOOKUP(K116,List!$B$1:$D$10,3,0) -> Resultado | N116: =LEFT(B116,2) -> 72 | O116: =VLOOKUP(N116,List!$F$1:$G$36,2,0) -> Mano De Obra Directa | P116: =LEFT(B116,4) -> 7205 | Q116: =VLOOKUP(P116,PUC!$A$7:$B$869,2,0) -> Mano de obra directa | R116: SI | S116: =VLOOKUP(N116,List!$F:$H,3,0) -> 0
A117: 815 | B117: 72052401 | C117: Incapacidades | D117: Gasto - Nómina | E117: Costos de producción o de operación | F117: Sin asignar | G117: No maneja vencimiento | H117: No | I117: Sí | J117: Transaccional | K117: =VALUE(LEFT(B117)) -> 7 | L117: =VLOOKUP(K117,List!$B$1:$D$10,2,0) -> Costos de Servicios | M117: =VLOOKUP(K117,List!$B$1:$D$10,3,0) -> Resultado | N117: =LEFT(B117,2) -> 72 | O117: =VLOOKUP(N117,List!$F$1:$G$36,2,0) -> Mano De Obra Directa | P117: =LEFT(B117,4) -> 7205 | Q117: =VLOOKUP(P117,PUC!$A$7:$B$869,2,0) -> Mano de obra directa | R117: SI | S117: =VLOOKUP(N117,List!$F:$H,3,0) -> 0
A118: 817 | B118: 72052701 | C118: Auxilio de transporte | D118: Gasto - Nómina | E118: Costos de producción o de operación | F118: Sin asignar | G118: No maneja vencimiento | H118: No | I118: Sí | J118: Transaccional | K118: =VALUE(LEFT(B118)) -> 7 | L118: =VLOOKUP(K118,List!$B$1:$D$10,2,0) -> Costos de Servicios | M118: =VLOOKUP(K118,List!$B$1:$D$10,3,0) -> Resultado | N118: =LEFT(B118,2) -> 72 | O118: =VLOOKUP(N118,List!$F$1:$G$36,2,0) -> Mano De Obra Directa | P118: =LEFT(B118,4) -> 7205 | Q118: =VLOOKUP(P118,PUC!$A$7:$B$869,2,0) -> Mano de obra directa | R118: SI | S118: =VLOOKUP(N118,List!$F:$H,3,0) -> 0
A119: 819 | B119: 72053001 | C119: Cesantías | D119: Gasto - Nómina | E119: Costos de producción o de operación | F119: Sin asignar | G119: No maneja vencimiento | H119: No | I119: Sí | J119: Transaccional | K119: =VALUE(LEFT(B119)) -> 7 | L119: =VLOOKUP(K119,List!$B$1:$D$10,2,0) -> Costos de Servicios | M119: =VLOOKUP(K119,List!$B$1:$D$10,3,0) -> Resultado | N119: =LEFT(B119,2) -> 72 | O119: =VLOOKUP(N119,List!$F$1:$G$36,2,0) -> Mano De Obra Directa | P119: =LEFT(B119,4) -> 7205 | Q119: =VLOOKUP(P119,PUC!$A$7:$B$869,2,0) -> Mano de obra directa | R119: SI | S119: =VLOOKUP(N119,List!$F:$H,3,0) -> 0
A120: 821 | B120: 72053301 | C120: Intereses sobre cesantías | D120: Gasto - Nómina | E120: Costos de producción o de operación | F120: Sin asignar | G120: No maneja vencimiento | H120: No | I120: Sí | J120: Transaccional | K120: =VALUE(LEFT(B120)) -> 7 | L120: =VLOOKUP(K120,List!$B$1:$D$10,2,0) -> Costos de Servicios | M120: =VLOOKUP(K120,List!$B$1:$D$10,3,0) -> Resultado | N120: =LEFT(B120,2) -> 72 | O120: =VLOOKUP(N120,List!$F$1:$G$36,2,0) -> Mano De Obra Directa | P120: =LEFT(B120,4) -> 7205 | Q120: =VLOOKUP(P120,PUC!$A$7:$B$869,2,0) -> Mano de obra directa | R120: SI | S120: =VLOOKUP(N120,List!$F:$H,3,0) -> 0
A121: 823 | B121: 72053601 | C121: Prima de servicios | D121: Gasto - Nómina | E121: Costos de producción o de operación | F121: Sin asignar | G121: No maneja vencimiento | H121: No | I121: Sí | J121: Transaccional | K121: =VALUE(LEFT(B121)) -> 7 | L121: =VLOOKUP(K121,List!$B$1:$D$10,2,0) -> Costos de Servicios | M121: =VLOOKUP(K121,List!$B$1:$D$10,3,0) -> Resultado | N121: =LEFT(B121,2) -> 72 | O121: =VLOOKUP(N121,List!$F$1:$G$36,2,0) -> Mano De Obra Directa | P121: =LEFT(B121,4) -> 7205 | Q121: =VLOOKUP(P121,PUC!$A$7:$B$869,2,0) -> Mano de obra directa | R121: SI | S121: =VLOOKUP(N121,List!$F:$H,3,0) -> 0
A122: 825 | B122: 72053901 | C122: Vacaciones | D122: Gasto - Nómina | E122: Costos de producción o de operación | F122: Sin asignar | G122: No maneja vencimiento | H122: No | I122: Sí | J122: Transaccional | K122: =VALUE(LEFT(B122)) -> 7 | L122: =VLOOKUP(K122,List!$B$1:$D$10,2,0) -> Costos de Servicios | M122: =VLOOKUP(K122,List!$B$1:$D$10,3,0) -> Resultado | N122: =LEFT(B122,2) -> 72 | O122: =VLOOKUP(N122,List!$F$1:$G$36,2,0) -> Mano De Obra Directa | P122: =LEFT(B122,4) -> 7205 | Q122: =VLOOKUP(P122,PUC!$A$7:$B$869,2,0) -> Mano de obra directa | R122: SI | S122: =VLOOKUP(N122,List!$F:$H,3,0) -> 0
... A130: 845 | B130: 72057801 | C130: Aportes Sena | D130: Gasto - Nómina | E130: Costos de producción o de operación | F130: Sin asignar | G130: No maneja vencimiento | H130: No | I130: Sí | J130: Transaccional | K130: =VALUE(LEFT(B130)) -> 7 | L130: =VLOOKUP(K130,List!$B$1:$D$10,2,0) -> Costos de Servicios | M130: =VLOOKUP(K130,List!$B$1:$D$10,3,0) -> Resultado | N130: =LEFT(B130,2) -> 72 | O130: =VLOOKUP(N130,List!$F$1:$G$36,2,0) -> Mano De Obra Directa | P130: =LEFT(B130,4) -> 7205 | Q130: =VLOOKUP(P130,PUC!$A$7:$B$869,2,0) -> Mano de obra directa | R130: SI | S130: =VLOOKUP(N130,List!$F:$H,3,0) -> 0
A131: 851 | B131: 73050501 | C131: Costos indirectos | D131: Costo de ventas | E131: Costos de producción o de operación | F131: Sin asignar | G131: No maneja vencimiento | H131: No | I131: Sí | J131: Transaccional | K131: =VALUE(LEFT(B131)) -> 7 | L131: =VLOOKUP(K131,List!$B$1:$D$10,2,0) -> Costos de Servicios | M131: =VLOOKUP(K131,List!$B$1:$D$10,3,0) -> Resultado | N131: =LEFT(B131,2) -> 73 | O131: =VLOOKUP(N131,List!$F$1:$G$36,2,0) -> Costos Indirectos | P131: =LEFT(B131,4) -> 7305 | Q131: =VLOOKUP(P131,PUC!$A$7:$B$8690,2,0) -> Costos indirectos | R131: SI | S131: =VLOOKUP(N131,List!$F:$H,3,0) -> 0
A132: 855 | B132: 74050501 | C132: Contratos de servicios | D132: Costo de ventas | E132: Costos de producción o de operación | F132: Sin asignar | G132: No maneja vencimiento | H132: No | I132: Sí | J132: Transaccional | K132: =VALUE(LEFT(B132)) -> 7 | L132: =VLOOKUP(K132,List!$B$1:$D$10,2,0) -> Costos de Servicios | M132: =VLOOKUP(K132,List!$B$1:$D$10,3,0) -> Resultado | N132: =LEFT(B132,2) -> 74 | O132: =VLOOKUP(N132,List!$F$1:$G$36,2,0) -> Contratos De Servicios | P132: =LEFT(B132,4) -> 7405 | Q132: =VLOOKUP(P132,PUC!$A$7:$B$8690,2,0) -> Contratos de servicios | R132: SI | S132: =VLOOKUP(N132,List!$F:$H,3,0) -> 0
A133: 795 | B133: 61350501 | C133: Comercio al por mayor y al por menor | D133: Costo de ventas | E133: Costos de venta | F133: Sin asignar | G133: No maneja vencimiento | H133: No | I133: Sí | J133: Transaccional | K133: =VALUE(LEFT(B133)) -> 6 | L133: =VLOOKUP(K133,List!$B$1:$D$10,2,0) -> Costos de Ventas | M133: =VLOOKUP(K133,List!$B$1:$D$10,3,0) -> Resultado | N133: =LEFT(B133,2) -> 61 | O133: =VLOOKUP(N133,List!$F$1:$G$36,2,0) -> Costo De Ventas Y De Prestación De Servicios | P133: =LEFT(B133,4) -> 6135 | Q133: =VLOOKUP(P133,PUC!$A$7:$B$869,2,0) -> Comercio al por mayor y al por menor | R133: SI | S133: =VLOOKUP(N133,List!$F:$H,3,0) -> 0
A134: 798 | B134: 61800101 | C134: Servicios | D134: Costo de ventas | E134: Costos de venta | F134: Sin asignar | G134: No maneja vencimiento | H134: No | I134: Sí | J134: Transaccional | K134: =VALUE(LEFT(B134)) -> 6 | L134: =VLOOKUP(K134,List!$B$1:$D$10,2,0) -> Costos de Ventas | M134: =VLOOKUP(K134,List!$B$1:$D$10,3,0) -> Resultado | N134: =LEFT(B134,2) -> 61 | O134: =VLOOKUP(N134,List!$F$1:$G$36,2,0) -> Costo De Ventas Y De Prestación De Servicios | P134: =LEFT(B134,4) -> 6180 | Q134: =VLOOKUP(P134,PUC!$A$7:$B$869,2,0) -> Servicios | R134: SI | S134: =VLOOKUP(N134,List!$F:$H,3,0) -> 0
A135: 862 | B135: 99999999 | C135: Saldos iniciales por conciliar | D135: Orden | E135: Cuentas de orden acreedoras | F135: Cuenta Puente | G135: No maneja vencimiento | H135: No | I135: Sí | J135: Transaccional | K135: =VALUE(LEFT(B135)) -> 9 | L135: =VLOOKUP(K135,List!$B$1:$D$10,2,0) -> Orden | M135: =VLOOKUP(K135,List!$B$1:$D$10,3,0) -> Orden | N135: =LEFT(B135,2) -> 99 | O135: =VLOOKUP(N135,List!$F$1:$G$36,2,0) -> Cuentas De Orden Acreedoras | P135: =LEFT(B135,4) -> 9999 | Q135: =VLOOKUP(P135,PUC!$A$7:$B$8690,2,0) -> Saldos iniciales por conciliar | R135: NO | S135: =VLOOKUP(N135,List!$F:$H,3,0) -> 0
A136: 464 | B136: 51050301 | C136: Salario integral | D136: Gasto - Nómina | E136: Gastos | F136: Sin asignar | G136: No maneja vencimiento | H136: No | I136: Sí | J136: Transaccional | K136: =VALUE(LEFT(B136)) -> 5 | L136: =VLOOKUP(K136,List!$B$1:$D$10,2,0) -> Gastos | M136: =VLOOKUP(K136,List!$B$1:$D$10,3,0) -> Resultado | N136: =LEFT(B136,2) -> 51 | O136: =VLOOKUP(N136,List!$F$1:$G$36,2,0) -> Administrativos | P136: =LEFT(B136,4) -> 5105 | Q136: =VLOOKUP(P136,PUC!$A$7:$B$869,2,0) -> Gastos de personal | R136: SI | S136: =VLOOKUP(N136,List!$F:$H,3,0) -> 0
...

Sheet List
B1: Clase | C1: Nombre Clase | D1: Tipo | F1: Grupo | G1: Nombre Grupo | H1: Tipo
B2: 1 | C2: Activo | D2: Balance | F2: 11 | G2: =PROPER(VLOOKUP(F2,PUC!$A$7:$I$869,2,0)) -> Efectivo Y Equivalentes De Efectivo | H2: Corto Termino
B3: 2 | C3: Pasivo | D3: Balance | F3: 12 | G3: =PROPER(VLOOKUP(F3,PUC!$A$7:$I$869,2,0)) -> Inversiones En Asociadas | H3: Corto Termino
B4: 3 | C4: Patrimonio | D4: Balance | F4: 13 | G4: =PROPER(VLOOKUP(F4,PUC!$A$7:$I$869,2,0)) -> Deudores Comerciales Y Otras Cuentas Por Cobrar | H4: Corto Termino
B5: 4 | C5: Ingresos | D5: Resultado | F5: 14 | G5: =PROPER(VLOOKUP(F5,PUC!$A$7:$I$869,2,0)) -> Inventarios | H5: Corto Termino
B6: 5 | C6: Gastos | D6: Resultado | F6: 15 | G6: =PROPER(VLOOKUP(F6,PUC!$A$7:$I$869,2,0)) -> Propiedad Planta Y Equipo | H6: Largo Termino
B7: 6 | C7: Costos de Ventas | D7: Resultado | F7: 16 | G7: =PROPER(VLOOKUP(F7,PUC!$A$7:$I$869,2,0)) -> Intangibles | H7: Largo Termino
B8: 7 | C8: Costos de Servicios | D8: Resultado | F8: 17 | G8: =PROPER(VLOOKUP(F8,PUC!$A$7:$I$869,2,0)) -> Otros Activos No Financieros | H8: Largo Termino
B9: 8 | C9: Orden | D9: Orden | F9: 18 | G9: =PROPER(VLOOKUP(F9,PUC!$A$7:$I$869,2,0)) -> Impuesto A Las Ganancias | H9: Corto Termino
B10: 9 | C10: Orden | D10: Orden | F10: 19 | G10: =PROPER(VLOOKUP(F10,PUC!$A$7:$I$869,2,0)) -> Otros Activos Financieros | H10: Corto Termino
F11: 71 | G11: =PROPER(VLOOKUP(F11,PUC!$A$7:$I$869,2,0)) -> Costos De Producción O De Operación
F12: 72 | G12: =PROPER(VLOOKUP(F12,PUC!$A$7:$I$869,2,0)) -> Mano De Obra Directa
F13: 73 | G13: =PROPER(VLOOKUP(F13,PUC!$A$7:$I$8690,2,0)) -> Costos Indirectos
F14: 74 | G14: =PROPER(VLOOKUP(F14,PUC!$A$7:$I$8690,2,0)) -> Contratos De Servicios
F15: 61 | G15: =PROPER(VLOOKUP(F15,PUC!$A$7:$I$869,2,0)) -> Costo De Ventas Y De Prestación De Servicios
F16: 99 | G16: =PROPER(VLOOKUP(F16,PUC!$A$7:$I$8690,2,0)) -> Cuentas De Orden Acreedoras
F17: 51 | G17: =PROPER(VLOOKUP(F17,PUC!$A$7:$I$869,2,0)) -> Administrativos
F18: 52 | G18: =PROPER(VLOOKUP(F18,PUC!$A$7:$I$869,2,0)) -> Ventas
F19: 53 | G19: =PROPER(VLOOKUP(F19,PUC!$A$7:$I$869,2,0)) -> Otros Gastos De Actividades Ordinarias
F20: 54 | G20: =PROPER(VLOOKUP(F20,PUC!$A$7:$I$869,2,0)) -> Impuesto De Renta Y Complementarios
F21: 41 | G21: =PROPER(VLOOKUP(F21,PUC!$A$7:$I$869,2,0)) -> Ingresos De Actividades Ordinarias
F22: 42 | G22: =PROPER(VLOOKUP(F22,PUC!$A$7:$I$869,2,0)) -> Otros Ingresos De Actividades Ordinarias
F23: 43 | G23: =PROPER(VLOOKUP(F23,PUC!$A$7:$I$869,2,0)) -> Ganancias
F24: 44 | G24: =PROPER(VLOOKUP(F24,PUC!$A$7:$I$869,2,0)) -> Ingresos Fiscales
F25: 21 | G25: =PROPER(VLOOKUP(F25,PUC!$A$7:$I$869,2,0)) -> Pasivos Financieros | H25: Corto Termino
F26: 22 | G26: =PROPER(VLOOKUP(F26,PUC!$A$7:$I$869,2,0)) -> Proveedores | H26: Corto Termino
F27: 23 | G27: =PROPER(VLOOKUP(F27,PUC!$A$7:$I$869,2,0)) -> Acreedores Comerciales Y Otras Cuentas Por Pagar | H27: Corto Termino
F28: 24 | G28: =PROPER(VLOOKUP(F28,PUC!$A$7:$I$869,2,0)) -> Pasivos Por Impuestos | H28: Corto Termino
F29: 25 | G29: =PROPER(VLOOKUP(F29,PUC!$A$7:$I$869,2,0)) -> Beneficios A Empleados | H29: Corto Termino
F30: 28 | G30: =PROPER(VLOOKUP(F30,PUC!$A$7:$I$869,2,0)) -> Pasivos No Financieros | H30: Corto Termino
F31: 31 | G31: =PROPER(VLOOKUP(F31,PUC!$A$7:$I$869,2,0)) -> Capital Social
F32: 32 | G32: =PROPER(VLOOKUP(F32,PUC!$A$7:$I$869,2,0)) -> Superávit De Capital
F33: 33 | G33: =PROPER(VLOOKUP(F33,PUC!$A$7:$I$869,2,0)) -> Reservas
F34: 36 | G34: =PROPER(VLOOKUP(F34,PUC!$A$7:$I$869,2,0)) -> Resultados Del Ejercicio
F35: 37 | G35: =PROPER(VLOOKUP(F35,PUC!$A$7:$I$869,2,0)) -> Resultados De Ejercicios Anteriores
F36: 39 | G36: =PROPER(VLOOKUP(F36,PUC!$A$7:$I$869,2,0)) -> Afectaciones Fiscales De Ingresos Y Gastos

Sheet PUC
A2: Cuentas contables
A3: MAS CONSULTA SAS
A4: 901271750-
A7: Código | B7: Nombre | C7: Categoría | D7: Clase | E7: Relación con | F7: Maneja vencimientos | G7: Diferencia fiscal | H7: Activo | I7: Nivel agrupación
A8: 1 | B8: Activo
A9: 11 | B9: Efectivo y equivalentes de efectivo
A10: 1105 | B10: Caja
A11: 110505 | B11: Caja general
A12: 11050501 | B12: Caja general | C12: Caja - Bancos | D12: Activo | E12: Sin asignar | F12: No maneja vencimiento | G12: No | H12: Sí | I12: Transaccional
A13: 110510 | B13: Cajas menores
A14: 11051001 | B14: Cajas menores | C14: Caja - Bancos | D14: Activo | E14: Sin asignar | F14: No maneja vencimiento | G14: No | H14: Sí | I14: Transaccional
A15: 11051002 | B15: Caja Menor Admon | C15: Caja - Bancos | D15: Activo | E15: Sin asignar | F15: No maneja vencimiento | G15: No | H15: Sí | I15: Transaccional
A16: 1110 | B16: Bancos
A17: 111005 | B17: Moneda nacional
A18: 11100501 | B18: Moneda nacional | C18: Caja - Bancos | D18: Activo | E18: Sin asignar | F18: No maneja vencimiento | G18: No | H18: Sí | I18: Transaccional
A19: 11100502 | B19: Pagos en línea | C19: Caja - Bancos | D19: Activo | E19: Formas de pago | F19: No maneja vencimiento | G19: No | H19: Sí | I19: Transaccional
A20: 11100503 | B20: Pagos en línea Mercado Pago | C20: Caja - Bancos | D20: Activo | E20: Formas de pago | F20: No maneja vencimiento | G20: No | H20: Sí | I20: Transaccional
A21: 1120 | B21: Cuentas de ahorro
A22: 112005 | B22: Bancos
A23: 11200501 | B23: BANCOLOMBIA CUENTA AHORROS 206-000311-48 | C23: Caja - Bancos | D23: Activo | E23: Sin asignar | F23: No maneja vencimiento | G23: No | H23: Sí | I23: Transaccional
A24: 11200502 | B24: CAJA SOCIAL CUENTA AHORROS 24097494078 | C24: Caja - Bancos | D24: Activo | E24: Sin asignar | F24: No maneja vencimiento | G24: No | H24: Sí | I24: Transaccional
A25: 1145 | B25: Inversiones en efectivo
A26: 114505 | B26: Fiducias
A27: 11450501 | B27: Fiducias | C27: Caja - Bancos | D27: Activo | E27: Sin asignar | F27: No maneja vencimiento | G27: No | H27: Sí | I27: Transaccional
A28: 11450597 | B28: D. fiscal fiducias | C28: Caja - Bancos | D28: Activo | E28: Sin asignar | F28: No maneja vencimiento | G28: Sí | H28: Sí | I28: Transaccional
A29: 12 | B29: Inversiones en asociadas
A30: 1205 | B30: Acciones
A31: 120535 | B31: Comercio al por mayor y al por menor
A32: 12053501 | B32: Comercio al por mayor y al por menor | C32: Otros activos | D32: Activo | E32: Sin asignar | F32: No maneja vencimiento | G32: No | H32: Sí | I32: Transaccional
A33: 12053502 | B33: Reajuste fiscal | C33: Otros activos | D33: Activo | E33: Sin asignar | F33: No maneja vencimiento | G33: No | H33: Sí | I33: Transaccional
A34: 12053503 | B34: Método de participación | C34: Otros activos | D34: Activo | E34: Sin asignar | F34: No maneja vencimiento | G34: No | H34: Sí | I34: Transaccional
A35: 1295 | B35: Acciones o derechos en clubes deportivos
A36: 129515 | B36: Acciones o derechos en clubes deportivos
A37: 12951501 | B37: Acciones o derechos en clubes deportivos | C37: Otros activos | D37: Activo | E37: Sin asignar | F37: No maneja vencimiento | G37: No | H37: Sí | I37: Transaccional
A38: 129595 | B38: Otras inversiones
A39: 12959501 | B39: Otras inversiones | C39: Otros activos | D39: Activo | E39: Sin asignar | F39: No maneja vencimiento | G39: No | H39: Sí | I39: Transaccional
A40: 13 | B40: Deudores comerciales y otras cuentas por cobrar
A41: 1305 | B41: Clientes nacionales
A42: 130505 | B42: Clientes nacionales
A43: 13050501 | B43: Clientes nacionales | C43: Cuentas por cobrar | D43: Activo | E43: Sin asignar | F43: Con vencimiento en cartera | G43: No | H43: Sí | I43: Transaccional
...
